<?xml version="1.0"?>
<robot name="rtklawnmower">
  <link name="base_footprint">
    <visual>
      <origin rpy="0 0 0" xyz="0 0 0"/>
      <geometry>
        <box size="0.001 0.001 0.001"/>
      </geometry>
    </visual>
  </link>
  <joint name="base_footprint_joint" type="fixed">
    <origin xyz="0 0 0.06" rpy="0 0 0"/>
    <parent link="base_footprint"/>
    <child link="base_link"/>
  </joint>
  <link name="base_link">
    <visual>
      <origin xyz="0.1 0 0.12" rpy="0 0 0"/>
      <geometry>
        <box size="0.4 0.25 0.1"/>
      </geometry>
    </visual>
    <collision>
      <origin xyz="0.1 0 0.12" rpy="0 0 0"/>
      <geometry>
        <box size="0.40 0.25 0.10"/>
      </geometry>
    </collision>
    <inertial>
      <mass value="4"/>
      <origin xyz="0 0 0"/>
      <inertia ixx="${(1/12)*4*(0.25*0.25+0.10*0.10)}" ixy="0.0" ixz="0.0"
               iyy="${(1/12)*4*(0.40*0.40+0.10*0.10)}" iyz="0.0"
               izz="${(1/12)*4*(0.40*0.40+0.25*0.25)}" />
    </inertial>
  </link>
  <link name="right_wheel">
    <visual>
      <origin xyz="0 0 0" rpy="${pi/2} 0 0"/>
      <geometry>
        <cylinder length="0.08" radius="0.06"/>
      </geometry>
    </visual>
    <collision>
      <origin xyz="0 0 0" rpy="${pi/2} 0 0"/>
      <geometry>
        <cylinder length="0.08" radius="0.06"/>
      </geometry>
    </collision>
    <inertial>
      <mass value="0.5"/>
      <origin xyz="0 0 0"/>
      <inertia ixx="${(1/12)*0.5*(3*0.06*0.06+0.08*0.08)}" ixy="0.0" ixz="0.0"
               iyy="${(1/12)*0.5*(3*0.06*0.06+0.08*0.08)}" iyz="0.0"
               izz="${(1/2)*0.5*0.06*0.06}" />
    </inertial>
  </link>
  <joint name="right_wheel_joint" type="continuous">
    <parent link="base_link"/>
    <child link="right_wheel"/>
    <origin xyz="0.0 0.08 0.0" rpy="0 0 0"/>
    <axis rpy="0  0" xyz="0 1 0"/>
    <limit effort="100" velocity="100"/>
    <joint_properties damping="0.0" friction="0.0"/>
  </joint>
  <transmission name="right_wheel_joint_trans">
    <type>transmission_interface/SimpleTransmission</type>
    <joint name="right_wheel_joint"/>
    <actuator name="right_wheel_joint_motor">
      <hardwareInterface>EffortJointInterface</hardwareInterface>
      <mechanicalReduction>1</mechanicalReduction>
    </actuator>
  </transmission>
  <link name="left_wheel">
    <visual>
      <origin xyz="0 0 0" rpy="${pi/2} 0 0"/>
      <geometry>
        <cylinder length="0.08" radius="0.06"/>
      </geometry>
    </visual>
    <collision>
      <origin xyz="0 0 0" rpy="${pi/2} 0 0"/>
      <geometry>
        <cylinder length="0.08" radius="0.06"/>
      </geometry>
    </collision>
    <inertial>
      <mass value="0.5"/>
      <origin xyz="0 0 0"/>
      <inertia ixx="${(1/12)*0.5*(3*0.06*0.06+0.08*0.08)}" ixy="0.0" ixz="0.0"
               iyy="${(1/12)*0.5*(3*0.06*0.06+0.08*0.08)}" iyz="0.0"
               izz="${(1/2)*0.5*0.06*0.06}" />
    </inertial>
  </link>
  <joint name="left_wheel_joint" type="continuous">
    <parent link="base_link"/>
    <child link="left_wheel"/>
    <origin xyz="0.0 -0.08 0.0" rpy="0 0 0" />
    <axis rpy="0  0" xyz="0 1 0"/>
    <limit effort="100" velocity="100"/>
    <joint_properties damping="0.0" friction="0.0"/>
  </joint>
  <transmission name="left_wheel_joint_trans">
    <type>transmission_interface/SimpleTransmission</type>
    <joint name="left_wheel_joint"/>
    <actuator name="left_wheel_joint_motor">
      <hardwareInterface>EffortJointInterface</hardwareInterface>
      <mechanicalReduction>1</mechanicalReduction>
    </actuator>
  </transmission>
  <link name="caster_right_link">
    <visual>
      <origin xyz="0 0 0" rpy="${pi/2} 0 0"/>
      <geometry>
        <sphere radius="0.025"/>
      </geometry>
    </visual>
    <collision>
      <geometry>
        <sphere radius="0.025"/>
      </geometry>
      <origin xyz="0 0 0" rpy="${pi/2} 0 0"/>
    </collision>
    <inertial>
      <mass value="0.5"/>
      <origin xyz="0 0 0"/>
      <inertia ixx="0.001" ixy="0.0" ixz="0.0" iyy="0.001" iyz="0.0" izz="0.001"/>
    </inertial>
  </link>
  <joint name="caster_right_joint" type="fixed">
    <parent link="base_link"/>
    <child link="caster_right_link"/>
    <origin xyz="0.3 0.1 0.01" rpy="-${pi/2} 0 0"/>
  </joint>
  <link name="caster_left_link">
    <visual>
      <origin xyz="0 0 0" rpy="${pi/2} 0 0"/>
      <geometry>
        <sphere radius="0.025"/>
      </geometry>
    </visual>
    <collision>
      <geometry>
        <sphere radius="0.025"/>
      </geometry>
      <origin xyz="0 0 0" rpy="${pi/2} 0 0"/>
    </collision>
    <inertial>
      <mass value="0.5"/>
      <origin xyz="0 0 0"/>
      <inertia ixx="0.001" ixy="0.0" ixz="0.0" iyy="0.001" iyz="0.0" izz="0.001"/>
    </inertial>
  </link>
  <joint name="caster_left_joint" type="fixed">
    <parent link="base_link"/>
    <child link="caster_left_link"/>
    <origin xyz="0.3 -0.1 0.01" rpy="-${pi/2} 0 0"/>
  </joint>
  
  <gazebo>
    <plugin filename="libgazebo_ros_diff_drive.so" name="gazebo_diffdrive_control">
      <rosDebugLevel>Debug</rosDebugLevel>
      <publishWheelTF>True</publishWheelTF>
      <publishTf>1</publishTf>
      <publishWheelJointState>true</publishWheelJointState>
      <alwaysOn>true</alwaysOn>
      <updateRate>100.0</updateRate>
      <leftJoint>left_wheel_joint</leftJoint>
      <rightJoint>right_wheel_joint</rightJoint>
      <wheelSeparation>0.16</wheelSeparation>
      <wheelDiameter>0.06</wheelDiameter>
      <broadcastTF>1</broadcastTF>
      <wheelTorque>30</wheelTorque>
      <wheelAcceleration>1.8</wheelAcceleration>
      <commandTopic>cmd_vel</commandTopic>
      <odometryFrame>odom</odometryFrame>
      <odometryTopic>odom</odometryTopic>
      <robotBaseFrame>base_link</robotBaseFrame>
    </plugin>
  </gazebo>

</robot>
