<?xml version="1.0"?>
<robot xmlns:xacro="http://www.ros.org/wiki/xacro" name="rtklawnmower">
  <xacro:macro name="wheel" params="prefix radius length mass joint_offset">
    
    <link name="${prefix}_wheel">
        <visual>
            <origin xyz="0 0 0" rpy="${pi/2} 0 0"/>
            <geometry>
                <cylinder length="${length}" radius="${radius}"/>
            </geometry>
        </visual>
        <collision>
            <origin xyz="0 0 0" rpy="${pi/2} 0 0"/>
            <geometry>
                <cylinder length="${length}" radius="${radius}"/>
            </geometry>
        </collision>
        <inertial>
            <origin xyz="0 0 0" rpy="${pi/2} 0 0"/>
            <mass value="${mass}"/>
            <inertia ixx="${(1/12) * mass * (3*radius*radius + length*length)}" ixy="0.0" ixz="0.0"
                     iyy="${(1/12) * mass * (3*radius*radius + length*length)}" iyz="0.0"
                     izz="${(1/2)  * mass * (radius*radius)}" />
        </inertial>
    </link>

    <joint name="${prefix}_wheel_joint" type="continuous">
        <axis xyz="0 1 0"/>
        <parent link="base_link"/>
        <child link="${prefix}_wheel"/>
        <origin xyz="${joint_offset}" rpy="0 0 0"/>
        <limit effort="100" velocity="100"/>
    </joint>

    <transmission name="${prefix}_wheel_transmission">
        <type>transmission_interface/SimpleTransmission</type>
        <actuator name="${prefix}_wheel_motor">
            <mechanicalReduction>1</mechanicalReduction>
            <hardwareInterface>hardware_interface/VelocityJointInterface</hardwareInterface>
        </actuator>
        <joint name="${prefix}_wheel_joint">
            <hardwareInterface>hardware_interface/VelocityJointInterface</hardwareInterface>
        </joint>
    </transmission>

    <gazebo reference="${prefix}_wheel">
      <mu1 value="1.0"/>
      <mu2 value="1.0"/>
      <kp  value="10000000.0" />
      <kd>100.0</kd>
      <minDepth>0.001</minDepth>
      <maxVel>0.1</maxVel>
      <material>Gazebo/FlatBlack</material>
    </gazebo>

  </xacro:macro>
</robot>